<?xml version="1.0"?>
<robot xmlns:xacro="http://ros.org/wiki/xacro">
  <!-- include gazebo file -->
  <xacro:include filename="$(find robotiq_c2_description)/urdf/robotiq_c2.gazebo"/>

  <!-- include transmission file -->
  <xacro:include filename="$(find robotiq_c2_description)/urdf/robotiq_c2.transmission.xacro"/>

  <!-- define xacro property (Optional) -->
  <xacro:property name="mass" value="1"/>
  <xacro:property name="scaling" value="10"/> <!-- set to 10 to avoid model jittering -->

  <!-- define macro that will be used frequently later on (Optional) -->

  <!-- define macro for our main robot model -->
  <xacro:macro name="robotiq_c2_model" params="prefix">
    <!-- links and joints of the robot main body -->
    <link name="${prefix}robotiq_85_adapter_link">
      <visual>
        <geometry>
          <mesh filename="package://robotiq_c2_description/meshes/robotiq_c2/visual/robotiq_85_gripper_adapter_plate.dae"/>
        </geometry>
        <origin rpy="1.5707 0 1.5707" xyz="0 0 0"/>
      </visual>
      <collision>
        <geometry>
          <mesh filename="package://robotiq_c2_description/meshes/robotiq_c2/collision/robotiq_85_gripper_adapter_plate.dae"/>
        </geometry>
        <origin rpy="0 0 1.5707" xyz="0 0 0"/>
      </collision>
      <inertial>
        <origin xyz="0.000000 -0.004250 0.000000" rpy="0 0 0"/>
        <mass value="${mass}"/>
        <inertia ixx="${ 1 *scaling}" ixy="0" ixz="0" iyy="${ 1 *scaling}" iyz="0" izz="${ 1 *scaling}"/>
      </inertial>
    </link>

    <joint name="${prefix}robotiq_85_base_joint" type="fixed">
      <parent link="${prefix}robotiq_85_adapter_link"/>
      <child link="${prefix}robotiq_85_base_link"/>
      <axis xyz="1 0 0"/>
      <origin rpy="0 0 0" xyz=".0085 0 -.0041"/>
    </joint>

    <link name="${prefix}robotiq_85_base_link">
      <visual>
        <geometry>
          <mesh filename="package://robotiq_c2_description/meshes/robotiq_c2/visual/robotiq_85_gripper_base.dae"/>
        </geometry>
        <origin rpy="3.1415 0 1.5707" xyz="0 0 0"/>
      </visual>
      <collision>
        <geometry>
          <mesh filename="package://robotiq_c2_description/meshes/robotiq_c2/collision/robotiq_85_gripper_base.dae"/>
        </geometry>
        <origin rpy="1.5707 0 1.5707" xyz="0 0 0"/>
      </collision>
      <inertial>
        <origin xyz="-0.001233 -0.000453 0.026359" rpy="0 0 0"/>
        <mass value="${mass}"/>
        <inertia ixx="${ 0.024233 *scaling}" ixy="${ 0.000455 *scaling}" ixz="${ -0.000422 *scaling}" iyy="${ 0.067403 *scaling}" iyz="${ 0.002943 *scaling}" izz="${ 0.059916 *scaling}"/>
      </inertial>
    </link>

    <joint name="${prefix}robotiq_85_left_knuckle_joint" type="revolute">
      <parent link="${prefix}robotiq_85_base_link"/>
      <child link="${prefix}robotiq_85_left_knuckle_link"/>
      <axis xyz="1 0 0"/>
      <origin rpy="-1.5707 1.5707 0" xyz=".04191 .0306 0"/>
      <limit lower="0" upper=".8575" velocity="2.0" effort="1000"/>
      <dynamics damping="0.0" fraction="0.0"/>
    </joint>

    <link name="${prefix}robotiq_85_left_knuckle_link">
      <visual>
        <geometry>
          <mesh filename="package://robotiq_c2_description/meshes/robotiq_c2/visual/robotiq_85_gripper_joint_0_L.dae"/>
        </geometry>
        <origin rpy="3.14159 -1.5707 0" xyz="0 .04191 -.0306"/>
      </visual>
      <collision>
        <geometry>
          <mesh filename="package://robotiq_c2_description/meshes/robotiq_c2/collision/robotiq_85_gripper_joint_0_L.dae"/>
        </geometry>
        <origin rpy="1.5707 -1.5707 0" xyz="0 .04191 -.0306"/>
      </collision>
      <inertial>
        <origin xyz="0.044585 -0.011112 0.039608" rpy="0 0 0"/>
        <mass value="${mass}"/>
        <inertia ixx="${ 0.000255 * scaling}" ixy="${ 0 *scaling}" ixz="${ 0.000046 * scaling}" iyy="${ 0.000366 *scaling}" iyz="${ 0 *scaling}" izz="${ 0.000537 *scaling}"/>
      </inertial>
    </link> 

    <joint name="${prefix}robotiq_85_right_knuckle_joint" type="revolute">
      <parent link="${prefix}robotiq_85_base_link"/>
      <child link="${prefix}robotiq_85_right_knuckle_link"/>
      <axis xyz="1 0 0"/>
      <origin rpy="1.5707 -1.5707 0" xyz=".04191 -.0306 0"/>
      <limit lower="0" upper="1.5707" velocity="2.0" effort="1000"/>
      <dynamics damping="0.0" fraction="0.0"/>
      <mimic joint="${prefix}robotiq_85_left_knuckle_joint" multiplier="1"/>
    </joint>


    <link name="${prefix}robotiq_85_right_knuckle_link">
      <visual>
        <geometry>
          <mesh filename="package://robotiq_c2_description/meshes/robotiq_c2/visual/robotiq_85_gripper_joint_0_R.dae"/>
        </geometry>
        <origin rpy="3.14159 1.5707 0" xyz="0 .04191 -.0306"/>
      </visual>
      <collision>
        <geometry>
          <mesh filename="package://robotiq_c2_description/meshes/robotiq_c2/collision/robotiq_85_gripper_joint_0_R.dae"/>
        </geometry>
        <origin rpy="1.5707 1.5707 0" xyz="0 .04191 -.0306"/>
      </collision>
      <inertial>
        <origin xyz="-0.0448812 -0.0111123 0.0395300" rpy="0 0 0"/>
        <mass value="${mass}"/>
        <inertia ixx="${ 0.000255 * scaling}" ixy="${ 0 *scaling}" ixz="${ 0.000046 * scaling}" iyy="${ 0.000366 *scaling}" iyz="${ 0 *scaling}" izz="${ 0.000537 *scaling}"/>
      </inertial>
    </link>

    <joint name="${prefix}robotiq_85_left_finger_joint" type="fixed">
      <parent link="${prefix}robotiq_85_left_knuckle_link"/>
      <child link="${prefix}robotiq_85_left_finger_link"/>
      <axis xyz="1 0 0"/>
      <origin rpy="3.1415 0 0" xyz="0 .00508 .03134"/>
      <limit lower="0" upper="1.5707" velocity="2.0" effort="1000"/>
    </joint>

    <link name="${prefix}robotiq_85_left_finger_link">
      <visual>
        <geometry>
          <mesh filename="package://robotiq_c2_description/meshes/robotiq_c2/visual/robotiq_85_gripper_joint_1_L.dae"/>
        </geometry>
        <origin rpy="0 1.5707 0" xyz="0 -.03683 .06194"/>
      </visual>
      <collision>
        <geometry>
          <mesh filename="package://robotiq_c2_description/meshes/robotiq_c2/collision/robotiq_85_gripper_joint_1_L.dae"/>
        </geometry>
        <origin rpy="-1.5707 1.5707 0" xyz="0 -.03683 .06194"/>
      </collision>
      <inertial>
        <origin xyz="0.065504 -0.011112 0.059293" rpy="0 0 0"/>
        <mass value="${mass}"/>
        <inertia ixx="${ 0.000662 * scaling}" ixy="${ 0 *scaling}" ixz="${ -0.000078 * scaling}" iyy="${ 0.000559 *scaling}" iyz="${ 0 *scaling}" izz="${ 0.000180 *scaling}"/>
      </inertial>
    </link> 

    <joint name="${prefix}robotiq_85_right_finger_joint" type="fixed">
      <parent link="${prefix}robotiq_85_right_knuckle_link"/>
      <child link="${prefix}robotiq_85_right_finger_link"/>
      <axis xyz="1 0 0"/>
      <origin rpy="3.1415 0 0" xyz="0 .00508 .03134"/>
      <limit lower="0" upper="1.5707" velocity="2.0" effort="1000"/>
    </joint>

    <link name="${prefix}robotiq_85_right_finger_link">
      <visual>
        <geometry>
          <mesh filename="package://robotiq_c2_description/meshes/robotiq_c2/visual/robotiq_85_gripper_joint_1_R.dae"/>
        </geometry>
        <origin rpy="0 -1.5707 0" xyz="0 -.03683 .06194"/>
      </visual>
      <collision>
        <geometry>
          <mesh filename="package://robotiq_c2_description/meshes/robotiq_c2/collision/robotiq_85_gripper_joint_1_R.dae"/>
        </geometry>
        <origin rpy="-1.5707 -1.5707 0" xyz="0 -.03683 .06194"/>
      </collision>
      <inertial>
        <origin xyz="-0.065504 -0.011112 0.059293" rpy="0 0 0"/>
        <mass value="${mass}"/>
        <inertia ixx="${ 0.000662 * scaling}" ixy="${ 0 *scaling}" ixz="${ -0.000078 * scaling}" iyy="${ 0.000559 *scaling}" iyz="${ 0 *scaling}" izz="${ 0.000180 *scaling}"/>
      </inertial>
    </link> 

    <joint name="${prefix}robotiq_85_left_inner_knuckle_joint" type="revolute">
      <parent link="${prefix}robotiq_85_base_link"/>
      <child link="${prefix}robotiq_85_left_inner_knuckle_link"/>
      <axis xyz="1 0 0"/>
      <origin rpy="1.5707 1.5707 0" xyz=".04843 .0127 0"/>
      <limit lower="0" upper="1.5707" velocity="2.0" effort="1000"/>
      <mimic joint="${prefix}robotiq_85_left_knuckle_joint" offset="0"/>
      <dynamics damping="0.0" fraction="0.0"/>
    </joint> 

    <link name="${prefix}robotiq_85_left_inner_knuckle_link">
      <visual>
        <geometry>
          <mesh filename="package://robotiq_c2_description/meshes/robotiq_c2/visual/robotiq_85_gripper_joint_2_L.dae"/>
        </geometry>
        <origin rpy="0 1.5707 0" xyz="0 -.04843 .0127"/>
      </visual>
      <collision>
        <geometry>
          <mesh filename="package://robotiq_c2_description/meshes/robotiq_c2/collision/robotiq_85_gripper_joint_2_L.dae"/>
        </geometry>
        <origin rpy="-1.5707 1.5707 0" xyz="0 -.04843 .0127"/>
      </collision>
      <inertial>
        <origin xyz="0.029215 -0.011113 0.066282" rpy="0 0 0"/>
        <mass value="${mass}"/>
        <inertia ixx="${ 0.000906 * scaling}" ixy="${ 0 *scaling}" ixz="${ -0.000542 * scaling}" iyy="${ 0.001192 *scaling}" iyz="${ 0 *scaling}" izz="${ 0.000822 *scaling}"/>
      </inertial>
    </link>

    <joint name="${prefix}robotiq_85_right_inner_knuckle_joint" type="revolute">
      <parent link="${prefix}robotiq_85_base_link"/>
      <child link="${prefix}robotiq_85_right_inner_knuckle_link"/>
      <axis xyz="1 0 0"/>
      <origin rpy="-1.5707 -1.5707 0" xyz=".04843 -.0127 0"/>
      <limit lower="0" upper="1.5707" velocity="2.0" effort="1000"/>
      <mimic joint="${prefix}robotiq_85_left_knuckle_joint" offset="0"/>
      <dynamics damping="0.0" fraction="0.0"/>
    </joint>


    <link name="${prefix}robotiq_85_right_inner_knuckle_link">
      <visual>
        <geometry>
          <mesh filename="package://robotiq_c2_description/meshes/robotiq_c2/visual/robotiq_85_gripper_joint_2_R.dae"/>
        </geometry>
        <origin rpy="0 -1.5707 0" xyz="0 -.04843 .0127"/>
      </visual>
      <collision>
        <geometry>
          <mesh filename="package://robotiq_c2_description/meshes/robotiq_c2/collision/robotiq_85_gripper_joint_2_R.dae"/>
        </geometry>
        <origin rpy="-1.5707 -1.5707 0" xyz="0 -.04843 .0127"/>
      </collision>
      <inertial>
        <origin xyz="-0.029215 -0.011112 0.066282" rpy="0.000000 0.000000 0.000000"/>
        <mass value="${mass}"/>
        <inertia ixx="0" ixy="0" ixz="0" iyy="0" iyz="0" izz="0"/>
      </inertial>
      <dynamics damping="0.0" fraction="0.0"/>
    </link>

    <joint name="${prefix}robotiq_85_left_finger_tip_joint" type="revolute">
      <parent link="${prefix}robotiq_85_left_inner_knuckle_link"/>
      <child link="${prefix}robotiq_85_left_finger_tip_link"/>
      <axis xyz="1 0 0"/>
      <origin rpy="0 0 0" xyz="0 .04196 -.0388"/>
      <limit lower="0" upper="1.5707" velocity="2.0" effort="1000"/>
      <mimic joint="${prefix}robotiq_85_left_knuckle_joint" multiplier="-1"/>
      <dynamics damping="0.0" fraction="0.0"/>
    </joint>

    <link name="${prefix}robotiq_85_left_finger_tip_link">
      <visual>
        <geometry>
          <mesh filename="package://robotiq_c2_description/meshes/robotiq_c2/visual/robotiq_85_gripper_joint_3_L.dae"/>
        </geometry>
        <origin rpy="0 1.5707 0" xyz="0 -.090381 .051505"/>
      </visual>
      <collision>
        <geometry>
          <mesh filename="package://robotiq_c2_description/meshes/robotiq_c2/collision/robotiq_85_gripper_joint_3_L.dae"/>
        </geometry>
        <origin rpy="-1.5707 1.5707 0" xyz="0 -.090381 .051505"/>
      </collision>
      <inertial>
        <origin xyz="0.056100 -0.011113 0.104316" rpy="0.000000 0.000000 0.000000"/>
        <mass value="${mass}"/>
        <inertia ixx="0" ixy="0" ixz="0" iyy="0" iyz="0" izz="0"/>
      </inertial>
    </link> 

    <joint name="${prefix}robotiq_85_right_finger_tip_joint" type="revolute">
      <parent link="${prefix}robotiq_85_right_inner_knuckle_link"/>
      <child link="${prefix}robotiq_85_right_finger_tip_link"/>
      <axis xyz="1 0 0"/>
      <origin rpy="0 0 0" xyz="0 .04196 -.0388"/>
      <limit lower="0" upper="1.5707" velocity="2.0" effort="1000"/>
      <mimic joint="${prefix}robotiq_85_left_knuckle_joint" multiplier="-1"/>
      <dynamics damping="0.0" fraction="0.0"/>
    </joint>

    <link name="${prefix}robotiq_85_right_finger_tip_link">
      <visual>
        <geometry>
          <mesh filename="package://robotiq_c2_description/meshes/robotiq_c2/visual/robotiq_85_gripper_joint_3_R.dae"/>
        </geometry>
        <origin rpy="0 -1.5707 0" xyz="0 -.090381 .051505"/>
      </visual>
      <collision>
        <geometry>
          <mesh filename="package://robotiq_c2_description/meshes/robotiq_c2/collision/robotiq_85_gripper_joint_3_R.dae"/>
        </geometry>
        <origin rpy="-1.5707 -1.5707 0" xyz="0 -.090381 .051505"/>
      </collision>
      <inertial>
        <origin xyz="-0.056100 -0.011112 0.104316" rpy="0.000000 0.000000 0.000000"/>
        <mass value="${mass}"/>
        <inertia ixx="0" ixy="0" ixz="0" iyy="0" iyz="0" izz="0"/>
      </inertial>
    </link>

    <!-- links and joints for additional sensor, e.g.camera -->

    <!-- create gazebo instance (no need here since we didn't define gazebo file as xacro:macro) -->

    <!-- create transmission instance -->
    <xacro:robotiq_c2_transmission prefix="${prefix}"/>
    
  </xacro:macro>
</robot>
